Workbook

Sheet Summary
B2: Apple Messages for Business
B3: Experience Review, validation summary
B4: Fill in the Checklist tab. This tab rolls up automatically. Scope comes from the Scope tab.
B6: Status breakdown
B7: Status | C7: Count
B8: Not Started | C8: =COUNTIF(Checklist!$I$3:$I$128,"Not Started") -> 114
B9: In Progress | C9: =COUNTIF(Checklist!$I$3:$I$128,"In Progress") -> 0
B10: Pass | C10: =COUNTIF(Checklist!$I$3:$I$128,"Pass") -> 0
B11: Fail | C11: =COUNTIF(Checklist!$I$3:$I$128,"Fail") -> 0
B12: Blocked | C12: =COUNTIF(Checklist!$I$3:$I$128,"Blocked") -> 0
B13: N/A | C13: =COUNTIF(Checklist!$I$3:$I$128,"N/A") -> 0
B14: Requires client testing | C14: =COUNTIF(Checklist!$I$3:$I$128,"Requires client testing") -> 0
B15: TBD | C15: =COUNTIF(Checklist!$I$3:$I$128,"TBD") -> 0
B16: Total test cases | C16: =COUNTA(Checklist!$B$3:$B$128) -> 114
B17: Pass rate of tested (Pass + Fail) | C17: =IFERROR(COUNTIF(Checklist!$I$3:$I$128,"Pass")/(COUNTIF(Checklist!$I$3:$I$128,"Pass")+COUNTIF(Checklist!$I$3:$I$128,"Fail")),0) -> 0
B19: Non-negotiable gate
B20: Failed or blocked non-negotiables | C20: =COUNTIFS(Checklist!$H$3:$H$128,"Non negotiable",Checklist!$I$3:$I$128,"Fail")+COUNTIFS(Checklist!$H$3:$H$128,"Non negotiable",Checklist!$I$3:$I$128,"Blocked") -> 0
B21: Any non-zero count here means the submission is not ready. These are checked on every Apple review.
B23: Coverage
B24: Rows in scope (not N/A) | C24: =COUNTA(Checklist!$B$3:$B$128)-COUNTIF(Checklist!$I$3:$I$128,"N/A") -> 114
B25: Rows marked N/A | C25: =COUNTIF(Checklist!$I$3:$I$128,"N/A") -> 0
B26: Rows with recording evidence logged | C26: =COUNTA(Checklist!$J$3:$J$128) -> 0
B27: In-scope rows still without evidence | C27: =COUNTA(Checklist!$B$3:$B$128)-COUNTIF(Checklist!$I$3:$I$128,"N/A")-COUNTA(Checklist!$J$3:$J$128) -> 114
B29: Fails by severity
B30: Non negotiable | C30: =COUNTIFS(Checklist!$H$3:$H$128,"Non negotiable",Checklist!$I$3:$I$128,"Fail") -> 0
B31: Apple standard | C31: =COUNTIFS(Checklist!$H$3:$H$128,"Apple standard",Checklist!$I$3:$I$128,"Fail") -> 0
B32: Field | C32: =COUNTIFS(Checklist!$H$3:$H$128,"Field",Checklist!$I$3:$I$128,"Fail") -> 0
B34: Fails by category
B35: Category | C35: Fail count
B36: 0. Final Gate (checked on every Apple review, see the Legend for Apple's five) | C36: =COUNTIFS(Checklist!$A$3:$A$128,"0. Final Gate (checked on every Apple review, see the Legend for Apple's five)",Checklist!$I$3:$I$128,"Fail") -> 0
B37: 1. Pre-Test and Review Readiness | C37: =COUNTIFS(Checklist!$A$3:$A$128,"1. Pre-Test and Review Readiness",Checklist!$I$3:$I$128,"Fail") -> 0
B38: 2. Entry Points and Passable Context | C38: =COUNTIFS(Checklist!$A$3:$A$128,"2. Entry Points and Passable Context",Checklist!$I$3:$I$128,"Fail") -> 0
B39: 3. Agent Identification, Honesty and Triage | C39: =COUNTIFS(Checklist!$A$3:$A$128,"3. Agent Identification, Honesty and Triage",Checklist!$I$3:$I$128,"Fail") -> 0
B40: 4. Core Messaging, Rich Links and Close | C40: =COUNTIFS(Checklist!$A$3:$A$128,"4. Core Messaging, Rich Links and Close",Checklist!$I$3:$I$128,"Fail") -> 0
B41: 5. Interactive Features | C41: =COUNTIFS(Checklist!$A$3:$A$128,"5. Interactive Features",Checklist!$I$3:$I$128,"Fail") -> 0
B42: 6. Attachments and Wallet Passes | C42: =COUNTIFS(Checklist!$A$3:$A$128,"6. Attachments and Wallet Passes",Checklist!$I$3:$I$128,"Fail") -> 0
B43: 7. Authentication, Apple Pay and Personal Data | C43: =COUNTIFS(Checklist!$A$3:$A$128,"7. Authentication, Apple Pay and Personal Data",Checklist!$I$3:$I$128,"Fail") -> 0
B44: 8. Device Capability and Fallback | C44: =COUNTIFS(Checklist!$A$3:$A$128,"8. Device Capability and Fallback",Checklist!$I$3:$I$128,"Fail") -> 0
B45: 9. Human Escalation and Live Agent Handoff | C45: =COUNTIFS(Checklist!$A$3:$A$128,"9. Human Escalation and Live Agent Handoff",Checklist!$I$3:$I$128,"Fail") -> 0
B46: 10. Policy, Consent and Conversational Design | C46: =COUNTIFS(Checklist!$A$3:$A$128,"10. Policy, Consent and Conversational Design",Checklist!$I$3:$I$128,"Fail") -> 0
...

Sheet Checklist
A1: Section | B1: Ref | C1: Test case | D1: Test steps | E1: Expected result | F1: Rule ref | G1: Applies when | H1: Severity | I1: Status | J1: Evidence (video + mm:ss) | K1: Actual result | L1: Comments
A2: 0. Final Gate (checked on every Apple review, see the Legend for Apple's five)
A3: 0. Final Gate (checked on every Apple review, see the Legend for Apple's five) | B3: 0.1 | C3: Reachable escalation | D3: Confirm a live agent connection is reachable within stated hours, OR the exempted callback or in conversation message path is offered and works end to end (see Section 9). | E3: Escalation path is reachable and functional. | F3: 2.3 | G3: Always | H3: Non negotiable | I3: Not Started
A4: 0. Final Gate (checked on every Apple review, see the Legend for Apple's five) | B4: 0.2 | C4: Leave Conversation respected | D4: End the conversation via Leave Conversation, then attempt to send from both the bot and a live agent. | E4: Both bot and human agent are blocked from sending; the business cannot re-engage until the user restarts. | F4: 2.9 | G4: Always | H4: Non negotiable | I4: Not Started
A5: 0. Final Gate (checked on every Apple review, see the Legend for Apple's five) | B5: 0.3 | C5: No forbidden or restricted platform wording | D5: Review every piece of bot copy, template text, interface label, localisation bundle, onboarding copy and spoken narration in the recording. | E5: No use of "iMessage", "AMB", "Apple Chat", "chat" or "text" as a channel name, and no wording implying Apple endorses the brand. Correct product naming throughout. | F5: 2.12 | G5: Always | H5: Non negotiable | I5: Not Started
A6: 0. Final Gate (checked on every Apple review, see the Legend for Apple's five) | B6: 0.4 | C6: Opt-out works end to end | D6: Trigger STOP / UNSUBSCRIBE / QUIT from an active, opted-in conversation. | E6: Both bot and live agent stop sending immediately; opt-out applies brand-wide, not just the current thread; re-engagement requires a fresh opt-in. | F6: 2.9 | G6: Always | H6: Non negotiable | I6: Not Started
A7: 1. Pre-Test and Review Readiness
A8: 1. Pre-Test and Review Readiness | B8: 1.1 | C8: Apple Messages for Business account connected and delivering | D8: Confirm the account is connected and send a test message. | E8: Message delivery is confirmed end to end. | F8: Doc 1 s4 | G8: Always | H8: Apple standard | I8: Not Started
A9: 1. Pre-Test and Review Readiness | B9: 1.2 | C9: Commercial account access restricted | D9: Check Account Testing then Advanced settings. | E9: Access is restricted to authorized Apple IDs used for testing. | F9: Doc 1 s4 | G9: Always | H9: Apple standard | I9: Not Started
A10: 1. Pre-Test and Review Readiness | B10: 1.3 | C10: All registered use cases are testable | D10: Cross-check the approved use case list on Appendix A against scenarios available in the test build. | E10: Every submitted use case has a corresponding, working flow in the test environment. | F10: Doc 1 s4 | G10: Always | H10: Apple standard | I10: Not Started
A11: 1. Pre-Test and Review Readiness | B11: 1.4 | C11: All entry points are functional | D11: Test each entry point marked in scope on Appendix A (URL button, Message Suggest, Apple Maps, Wallet, QR or App Store link, Business Invitation, IVR deflection, social). | E11: Each entry point opens a Messages conversation with the correct business account and correct routing context. | F11: 2.13 | G11: Always | H11: Apple standard | I11: Not Started
A12: 1. Pre-Test and Review Readiness | B12: 1.5 | C12: Agents trained, and an introduction script is defined | D12: Confirm with the client that live agent staff have been briefed, and review the written agent introduction script. | E12: Agents are prepared and trained for the channel and the relevant use cases, and a consistent introduction script exists. | F12: 2.3 | G12: Live agent in scope | H12: Apple standard | I12: Not Started
A13: 1. Pre-Test and Review Readiness | B13: 1.6 | C13: Tested on macOS as well as iPhone | D13: Run the primary use case from the Messages app on a Mac signed in to the same Apple ID. | E13: The experience works on macOS. iPhone is the priority platform, but macOS is also tested before submission. | F13: Doc 1 s4 | G13: Always | H13: Apple standard | I13: Not Started
A14: 1. Pre-Test and Review Readiness | B14: 1.7 | C14: Baseline metrics planned before launch | D14: Confirm with the client which metrics are captured and from when. | E14: Response times, resolution rates and satisfaction baselines are planned before launch, not after. | F14: 2.15 | G14: Always | H14: Apple standard | I14: Not Started
A15: 2. Entry Points and Passable Context
A16: 2. Entry Points and Passable Context | B16: 2.1 | C16: Entry point routing lands in the correct flow | D16: Open the conversation from each of the brand's registered entry points (for example two different QR codes for two different stores or intents). | E16: Each entry point routes to the correct, distinct flow, not the same generic flow regardless of source. | F16: 2.13 | G16: Always | H16: Apple standard | I16: Not Started
A17: 2. Entry Points and Passable Context | B17: 2.2 | C17: Bot confirms context received from entry point | D17: Open a conversation from an entry point carrying routing context (store, product or campaign reference). | E17: The opening message reflects the context received, for example "I see you're asking about [Store or Product X]", rather than a generic greeting. | F17: 2.4 | G17: Any entry point carrying context | H17: Apple standard | I17: Not Started
A18: 2. Entry Points and Passable Context | B18: 2.3 | C18: Business Invitation opt-in gate and decline handling | D18: Attempt to send a Business Invitation to a number that has not opted in; then send a valid test invite and respond "No" or decline. | E18: Platform requires opt-in coverage before sending; a decline is correctly registered and that user is not messaged again. | F18: 2.9 | G18: Business Invitations in scope | H18: Apple standard | I18: Not Started
A19: 2. Entry Points and Passable Context | B19: 2.4 | C19: Invitation opt-out present in every Business Update | D19: Review every Business Invitation and Business Update message the brand sends. | E19: Opt-out instructions appear in every single Business Update message, not just the first. | F19: 2.9 | G19: Business Invitations in scope | H19: Apple standard | I19: Not Started
A20: 2. Entry Points and Passable Context | B20: 2.5 | C20: A "Yes" on a Business Invitation is followed by a welcome that explains what was accepted | D20: Accept a Business Invitation and read the next message. | E20: An agent message welcomes the customer and states plainly what they signed up for, for example what notifications will be sent and how often. | F20: 2.6 | G20: Business Invitations in scope | H20: Apple standard | I20: Not Started
A21: 3. Agent Identification, Honesty and Triage
A22: 3. Agent Identification, Honesty and Triage | B22: 3.1 | C22: First response within 5 seconds, with typing indicator | D22: Send the first message of a new conversation and time the automated reply. | E22: A typing indicator appears first, then the automated response arrives within 5 seconds total. | F22: 2.4 | G22: Always | H22: Non negotiable | I22: Not Started
A23: 3. Agent Identification, Honesty and Triage | B23: 3.2 | C23: Bot self-identifies as automated on entry | D23: Review the opening automated message. | E23: Message clearly and plainly states it is an automated agent, not implied or buried. | F23: 2.4 | G23: Always | H23: Non negotiable | I23: Not Started
A24: 3. Agent Identification, Honesty and Triage | B24: 3.3 | C24: The opener states the assistant's name and what it covers | D24: Read the opening message after the disclosure. | E24: The opener names the assistant and states its scope, for example "I'm [NAME], here to help with orders, delivery and returns". Disclosure followed only by "what can we help you with?" does not satisfy this. | F24: 2.4 | G24: Always | H24: Apple standard | I24: Not Started
A25: 3. Agent Identification, Honesty and Triage | B25: 3.4 | C25: Bot answers truthfully when asked if it is a bot | D25: At multiple points in the conversation ask directly: "are you a bot?", "am I talking to a real person?", "are you AI?" | E25: Bot always answers truthfully that it is automated. It never claims to be human or dodges the question. | F25: 2.4 | G25: Always | H25: Non negotiable | I25: Not Started
A26: 3. Agent Identification, Honesty and Triage | B26: 3.5 | C26: Typing indicator before every outbound message, including rich features | D26: Step through a multi-message bot flow, including back-to-back sequences with no user input between them (enrollment confirmations, status updates, summaries, quick replies, forms). | E26: A typing indicator appears before every single outbound payload, not just the first, including one-off notifications, attachments, rich and interactive bubbles, the Authentication card and Apple Pay. | F26: 2.3 | G26: Always | H26: Non negotiable | I26: Not Started
A27: 3. Agent Identification, Honesty and Triage | B27: 3.6 | C27: Typing indicator never hangs or misleads | D27: Have a live agent leave a typing indicator active for an extended period without sending. | E27: Indicator resolves or refreshes sensibly rather than hanging indefinitely and implying an imminent reply that never comes. | F27: 2.3 | G27: Always | H27: Apple standard | I27: Not Started
A28: 3. Agent Identification, Honesty and Triage | B28: 3.7 | C28: Live agent messages also carry a typing indicator | D28: During a live agent exchange, watch the customer device while the agent composes. | E28: The typing indicator appears on the customer side for agent messages as well as bot messages. | F28: 2.3 | G28: Live agent in scope | H28: Apple standard | I28: Not Started
A29: 3. Agent Identification, Honesty and Triage | B29: 3.8 | C29: Triage menu appears when intent is unclear | D29: Send an ambiguous opening message such as "hi". | E29: Bot offers a Quick Reply triage menu of up to five options instead of guessing or forcing free text. | F29: 2.4 | G29: Always | H29: Apple standard | I29: Not Started
A30: 3. Agent Identification, Honesty and Triage | B30: 3.9 | C30: Triage menu leads with the most common options | D30: Compare the order of the menu options against real demand data. | E30: The most common reasons customers make contact appear first, and the list reflects real demand rather than an internal org chart. | F30: 2.5 | G30: Always | H30: Apple standard | I30: Not Started
A31: 3. Agent Identification, Honesty and Triage | B31: 3.10 | C31: A clearly written intent is answered rather than overridden by the menu | D31: Open the conversation with a specific, unambiguous request. | E31: The bot answers what was asked. It does not discard the stated intent and present the triage menu instead. | F31: 2.4 | G31: Always | H31: Apple standard | I31: Not Started
A32: 3. Agent Identification, Honesty and Triage | B32: 3.11 | C32: A route to a person appears on every menu | D32: Review every triage menu and sub-menu in the experience. | E32: Each menu includes an option to reach a person, or the agreed alternative path. | F32: 2.4 | G32: Always | H32: Apple standard | I32: Not Started
A33: 3. Agent Identification, Honesty and Triage | B33: 3.12 | C33: Triage is never more than two levels deep | D33: Walk the deepest menu path in the design. | E33: No path requires more than two menu selections before reaching a task or a person. | F33: 2.4 | G33: Always | H33: Apple standard | I33: Not Started
... A41: 3. Agent Identification, Honesty and Triage | B41: 3.20 | C41: Welcome message tone matches brand | D41: Review the welcome and greeting copy against brand voice guidelines. | E41: Tone is warm, on-brand, and not robotic or legalistic. | F41: 3.6 | G41: Always | H41: Field | I41: Not Started
A42: 4. Core Messaging, Rich Links and Close
A43: 4. Core Messaging, Rich Links and Close | B43: 4.1 | C43: Rich Links used for all URLs | D43: Review every message containing a URL, from the bot and from live agents. | E43: All URLs are sent as Rich Links. Plain-text and "tap-to-load" text links are not used anywhere. | F43: 2.7 | G43: Always | H43: Non negotiable | I43: Not Started
A44: 4. Core Messaging, Rich Links and Close | B44: 4.2 | C44: Rich Link logo image is properly sized | D44: Inspect the image used for any Rich Link built from a logo. | E44: Image is square or a rectangle with width under 150px, so it renders as a clean icon rather than a cropped or blurry preview. | F44: 2.7 | G44: Always | H44: Apple standard | I44: Not Started
A45: 4. Core Messaging, Rich Links and Close | B45: 4.3 | C45: Rich Link preview asset meets Apple's specification | D45: Inspect the preview asset file for a content Rich Link. | E45: PNG, optimised at 240 by 240 pixels, up to 200 kB. This is separate from the 150 pixel icon ceiling. | F45: 2.7 | G45: Always | H45: Apple standard | I45: Not Started
A46: 4. Core Messaging, Rich Links and Close | B46: 4.4 | C46: Every Rich Link image reflects the destination page | D46: Open each Rich Link and compare the preview image to the page it opens. | E46: The image reflects the page content rather than being a generic logo placeholder. Where the destination has no Open Graph image, one is generated before sending. | F46: 2.7 | G46: Always | H46: Apple standard | I46: Not Started
A47: 4. Core Messaging, Rich Links and Close | B47: 4.5 | C47: Video Rich Links have a background image | D47: Send every video Rich Link in the experience and view it on device. | E47: The preview renders with a background image. A black preview is a fast route to a review finding. | F47: 3.7 | G47: Video Rich Links in scope | H47: Field | I47: Not Started
...

Sheet Legend
B2: Legend and instructions
B4: How to use this template
B5: 1. Duplicate all five tabs for each new client or brand experience. Summary and Checklist read each other by name, so keep them together.
B6: 2. Fill in Appendix A first. It is the scope agreement, and it decides which rows apply. Appendix B is completed at the same stage but tests nothing.
B7: 3. Work through the Checklist against the live build. Use the Status dropdown in column I.
B8: 4. Mark a row N/A where the Applies when condition is not met on Appendix A.
B9: 5. Log evidence in column J as video and timestamp, for example V1 04:12. Exporting that column gives you the timestamp index Apple asks for alongside the recordings.
B10: 6. Summary rolls up automatically. Formulas recalculate on open.
B11: 7. Section 0 is a final pre-submission gate, not a re-test. It holds only the items not duplicated elsewhere. See the mapping below.
B13: The two appendices
B14: Appendix A and Appendix B reproduce Apple's own brand facing forms, Messages for Business Use Cases and Messages for Business Readiness Review. Apple recommends that brands complete both at the start of the engagement. They are included here so the answers sit alongside the tests they govern. Appendix A drives which rows apply. Appendix B is commercial and operational qualification and tests nothing against the build.
B16: Apple's five non-negotiables, and where each is tested
B17: Live agent escalation reachable, or the exempted path | C17: 0.1, and Section 9
B18: Opt-out works end to end | C18: 0.4, and 10.8
B19: No personal data requested in plain conversation | C19: 7.4 and 7.8
B20: Consent captured before any opt-in notification | C20: 10.1 and 10.2
B21: Capability aware fallback | C21: 8.1, 8.2 and 8.5
B22: Section 0 also carries two further gate items that are not among Apple's five but fail a review on their own: Leave Conversation respected (0.2) and no forbidden or restricted platform wording (0.3).
B24: Status values
B25: Not Started | C25: Not yet tested
B26: In Progress | C26: Testing underway
B27: Pass | C27: Meets the expected result
B28: Fail | C28: Does not meet the expected result
B29: Blocked | C29: Cannot be tested yet
B30: N/A | C30: Applies when condition not met for this build
B31: Requires client testing | C31: Only the client can verify, for example agent training
B32: TBD | C32: Scope or expectation not yet agreed
B34: Severity
B35: Non negotiable | C35: Checked on every Apple review. A failure blocks submission.
B36: Apple standard | C36: A documented Apple requirement. A failure is very likely to be returned.
B37: Field | C37: A Messaging Advisory observation. A failure is a quality risk, not an Apple rule.
B39: Reading the Ref column
B40: A reference shown in blue is new in this version. Rule ref points at the section of Document 2, the Conversation Design Standards and Best Practices, that the row tests. Doc 1 and Doc 4 references point at the Process Overview and the Recording Guide.
B42: Version and sources
B43: Template version | C43: 2.0
B44: Date | C44: 31 August 2026
B45: Derived from | C45: Conversation Design Standards and Best Practices v2.1
B46: Scope tab mirrors | C46: Apple, Messages for Business Use Cases form
B47: Previous version | C47: 63 test cases, 12 sections
B48: This version | C48: 114 test cases, 13 sections: 54 carried unchanged, 10 reworded or widened, 50 new
...

Sheet Apple Appendix A Scope
B6: Appendix A. Use case scope
B7: Apple, Messages for Business Use Cases
B8: This mirrors Apple's own Use Cases form, which Apple asks brands to complete at the start of the engagement. Reproduced here so the answers sit alongside the tests they govern.
B9: Fill the shaded cells. What you record here is the scope for the Checklist and the shot list for the recordings. Every 'Applies when' condition on the Checklist reads against it.
B11: Company information
B13: Brand name
B14: Definition of success | D14: One major achievement this channel should deliver
B15: Requested launch date
B16: Provider or MSP
B18: Entry points in scope
B20: Website Messages button | C20: No
B21: Message Suggest | C21: No | D21: Registered phone numbers, allow 5 to 7 days to propagate
B22: App Messages button | C22: No
B23: Social media links | C23: No
B24: IVR deflection | C24: No
B25: Apple Maps | C25: No
B26: QR codes | C26: No
B27: Wallet passes | C27: No
B28: Business Invitations | C28: No | D28: Drives rows 2.3, 2.4, 2.5
B29: Other, specify | C29: No
B31: General features in scope
B33: Automated welcome message | C33: No
B34: Satisfaction survey | C34: No | D34: Drives rows 10.5, 10.6
B35: Authentication | C35: No | D35: Drives rows 5.3, 7.1, 7.2
B36: Notifications and enrolment | C36: No | D36: Drives Section 10
B37: Live agent | C37: No | D37: Drives Section 9, and rows 1.5, 3.7, 8.4
B38: Multilingual | C38: No | D38: Drives rows 3.16, 3.17
B39: Account data returned in conversation | C39: No | D39: Drives row 7.2
B41: Enhanced features in scope
B43: Quick Reply | C43: No | D43: Drives row 4.13
B44: List Picker | C44: No | D44: Drives rows 5.4, 5.5
B45: Time Picker | C45: No | D45: Drives rows 5.12, 5.13
B46: Form | C46: No | D46: Drives rows 5.6 to 5.10
B47: Apple Pay | C47: No | D47: Drives rows 5.3, 7.3
B48: Rich Links | C48: No
B49: Video Rich Links | C49: No | D49: Drives row 4.5
B50: Maps or Apple Music payloads | C50: No | D50: Drives row 4.6
B51: Embedded app experience | C51: No
B52: Attachments: PDF, image, video | C52: No | D52: Drives row 6.1
B53: Wallet passes issued in conversation | C53: No | D53: Drives row 6.2
...

Sheet Apple Appendix B Readiness
B2: Appendix B. Readiness Review
B3: Apple, Messages for Business Readiness Review
B4: This mirrors Apple's own Readiness Review form, which Apple asks brands to complete before scope alignment. It qualifies the channel commercially and operationally. Nothing here is tested against a build.
B5: Fill the shaded cells. The containment figure and the cost per inquiry bands are the two answers Apple returns to most often, so give real numbers.
B7: Company information
B9: Brand name
B10: Industry vertical
B11: Country of headquarters
B12: Country coverage
B14: Digital priorities
B16: Digital deflection from the contact centre to self serve tools | D16: High, Medium or Low
B17: Driving consumer iOS app adoption | D17: High, Medium or Low
B18: Increasing customer experience metrics | D18: High, Medium or Low
B19: Reducing operational cost to sell and serve customers | D19: High, Medium or Low
B20: General call deflection from voice to digital channels | D20: High, Medium or Low
B21: Digital shift from web or live chat to asynchronous messaging | D21: High, Medium or Low
B22: Creating a digital sales engagement channel | D22: High, Medium or Low
B23: Improving collaboration between the contact centre and physical store or branch locations | D23: High, Medium or Low
B24: Securing conversation history for regulatory and internal audit purposes | D24: High, Medium or Low
B26: Strategy and operations
B28: A digital messaging platform is already in place | C28: No | D28: If yes, name the vendor in the notes column
B29: The digital messaging strategy is defined and executive sponsored | C29: No
B30: The business already engages customers in live or asynchronous messaging | C30: No
B31: The strategy includes AI or automation led conversations | C31: No | D31: If yes, state the anticipated containment percentage
B33: Volume and economics
B35: Anticipated containment from conversational AI | D35: Percentage
B36: Expected daily conversation capacity at launch
B37: Growth goal, daily conversations at 12 months
B38: Growth goal, daily conversations at 24 months
B39: Cost per inquiry, voice | D39: Band: 1 to 3, 4 to 8, 9 to 12, 12 plus
B40: Cost per inquiry, digital | D40: Band: 1 to 3, 4 to 8, 9 to 12, 12 plus
B41: Share of the digital customer base on Apple devices | D41: Under 50%, 50 to 75%, over 75%
B42: Live agents dedicated exclusively to this channel | D42: Yes or No
